# Twitter-Followup

Traceback (most recent call last): File "C:\Users\scvD\PycharmProjects\TwitterHound_2\venv\body.py", line 300, in check_for_followers(api,recent_following_user1,user_1,recent_following_user2,user_2,recent_following_user3,user_3,recent_following_user4,user_4,recent_following_user5,user_5,recent_following_user6,user_6,recent_following_user7,user_7,recent_following_user8,user_8,recent_following_user9,user_9,recent_following_user10,user_10,recent_following_user11,user_11) File "C:\Users\scvD\PycharmProjects\TwitterHound_2\venv\body.py", line 146, in check_for_followers requests.get(base_url) NameError: name 'base_url' is not defined

I'm getting this error all the time, line #300 is always in traceback and never changes, but lines with base URL like #146 are different every time.

Traceback (most recent call last): File "C:\Users\scvD\PycharmProjects\TwitterHound_2\venv\body.py", line 300, in check_for_followers(api,recent_following_user1,user_1,recent_following_user2,user_2,recent_following_user3,user_3,recent_following_user4,user_4,recent_following_user5,user_5,recent_following_user6,user_6,recent_following_user7,user_7,recent_following_user8,user_8,recent_following_user9,user_9,recent_following_user10,user_10,recent_following_user11,user_11) File "C:\Users\scvD\PycharmProjects\TwitterHound_2\venv\body.py", line 35, in check_for_followers requests.get(base_url) NameError: name 'base_url' is not defined
